//Control de errores asincronos
/* function errorAsincrono(cb){
    setTimeout(function(){
        try {
            return 3 + z;
        } catch (error) {
            console.log(error.message);
            cb(error);
        }        
    }, 1000);
}
errorAsincrono(function(){
    console.log('Hubo un error')
}) */

/* try {
    seRompe();    
} catch (err) {
    console.log('Hubo un error en la funcion seRompe');
    console.log(err.message);
    
        
}

console.log('Esto es un continuacion al error'); */
